Workbook

Sheet MOS
H1: SUBJECTS' RESULTS
B2: 1 | C2: 2 | D2: 3 | E2: 4 | F2: 5 | G2: 6 | H2: 7 | I2: 8 | J2: 9 | K2: 10 | L2: 11 | M2: 12 | N2: 13 | O2: 14 | P2: 15 | Q2: 16 | R2: 17 | S2: 18 | T2: 19 | U2: 20 | V2: 21 | W2: 22 | X2: 23 | Y2: 24 | Z2: 25 | AA2: 26 | AB2: 27 | AC2: 28 | AD2: 29 | AE2: 30 | AF2: 31 | AG2: 32 | AI2: MOS | AJ2: std | AK2: CI
A3: Fehn_c_Book_arrival_bh_8_to_10 | B3: 2 | C3: 1 | D3: 2 | E3: 3 | F3: 3 | G3: 2 | H3: 2 | I3: 4 | J3: 2 | K3: 1 | L3: 1 | M3: 2 | N3: 2 | O3: 2 | P3: 2 | Q3: 1 | R3: 3 | S3: 2 | T3: 2 | U3: 2 | V3: 3 | W3: 1 | X3: 2 | Y3: 3 | Z3: 3 | AA3: 3 | AB3: 4 | AC3: 2 | AD3: 2 | AE3: 3 | AF3: 2 | AG3: 2 | AI3: =AVERAGE(B3:AG3) -> 2.21875 | AJ3: =STDEVP(B3:AG3) -> 0.779999 | AK3: =1.96*AJ3/SQRT(32) -> 0.27025586
A4: Fehn_c_Book_arrival_bh_10_to_8 | B4: 2 | C4: 2 | D4: 2 | E4: 3 | F4: 3 | G4: 3 | H4: 2 | I4: 3 | J4: 4 | K4: 1 | L4: 1 | M4: 2 | N4: 2 | O4: 3 | P4: 3 | Q4: 1 | R4: 4 | S4: 1 | T4: 3 | U4: 2 | V4: 2 | W4: 2 | X4: 1 | Y4: 1 | Z4: 3 | AA4: 3 | AB4: 2 | AC4: 2 | AD4: 1 | AE4: 2 | AF4: 1 | AG4: 2 | AI4: =AVERAGE(B4:AG4) -> 2.15625 | AJ4: =STDEVP(B4:AG4) -> 0.86996318 | AK4: =1.96*AJ4/SQRT(32) -> 0.30142686
A5: Fehn_c_Book_arrival_sh_8_to_9 | B5: 4 | C5: 2 | D5: 4 | E5: 4 | F5: 3 | G5: 4 | H5: 4 | I5: 5 | J5: 3 | K5: 2 | L5: 3 | M5: 4 | N5: 4 | O5: 4 | P5: 3 | Q5: 2 | R5: 4 | S5: 4 | T5: 4 | U5: 3 | V5: 4 | W5: 3 | X5: 4 | Y5: 1 | Z5: 4 | AA5: 4 | AB5: 4 | AC5: 3 | AD5: 3 | AE5: 4 | AF5: 2 | AG5: 3 | AI5: =AVERAGE(B5:AG5) -> 3.40625 | AJ5: =STDEVP(B5:AG5) -> 0.86093608 | AK5: =1.96*AJ5/SQRT(32) -> 0.29829913
A6: Fehn_c_Book_arrival_sh_10_to_9 | B6: 4 | C6: 4 | D6: 3 | E6: 3 | F6: 3 | G6: 5 | H6: 4 | I6: 5 | J6: 5 | K6: 2 | L6: 2 | M6: 4 | N6: 3 | O6: 3 | P6: 3 | Q6: 4 | R6: 4 | S6: 4 | T6: 4 | U6: 4 | V6: 4 | W6: 4 | X6: 3 | Y6: 4 | Z6: 3 | AA6: 4 | AB6: 3 | AC6: 3 | AD6: 4 | AE6: 3 | AF6: 3 | AG6: 3 | AI6: =AVERAGE(B6:AG6) -> 3.5625 | AJ6: =STDEVP(B6:AG6) -> 0.7473913 | AK6: =1.96*AJ6/SQRT(32) -> 0.25895787
A7: Fehn_i_Book_arrival_bh_8_to_10 | B7: 3 | C7: 3 | D7: 2 | E7: 2 | F7: 2 | G7: 1 | H7: 1 | I7: 3 | J7: 3 | K7: 1 | L7: 1 | M7: 2 | N7: 2 | O7: 2 | P7: 1 | Q7: 1 | R7: 3 | S7: 1 | T7: 2 | U7: 2 | V7: 2 | W7: 2 | X7: 1 | Y7: 4 | Z7: 3 | AA7: 3 | AB7: 2 | AC7: 2 | AD7: 2 | AE7: 3 | AF7: 1 | AG7: 2 | AI7: =AVERAGE(B7:AG7) -> 2.03125 | AJ7: =STDEVP(B7:AG7) -> 0.80948962 | AK7: =1.96*AJ7/SQRT(32) -> 0.28047384
A8: Fehn_i_Book_arrival_bh_10_to_8 | B8: 3 | C8: 1 | D8: 3 | E8: 2 | F8: 2 | G8: 2 | H8: 2 | I8: 3 | J8: 3 | K8: 1 | L8: 1 | M8: 2 | N8: 2 | O8: 2 | P8: 2 | Q8: 1 | R8: 3 | S8: 1 | T8: 2 | U8: 3 | V8: 2 | W8: 2 | X8: 3 | Y8: 3 | Z8: 2 | AA8: 2 | AB8: 2 | AC8: 2 | AD8: 1 | AE8: 1 | AF8: 1 | AG8: 2 | AI8: =AVERAGE(B8:AG8) -> 2 | AJ8: =STDEVP(B8:AG8) -> 0.70710678 | AK8: =1.96*AJ8/SQRT(32) -> 0.245
A9: Fehn_i_Book_arrival_sh_8_to_9 | B9: 4 | C9: 2 | D9: 4 | E9: 3 | F9: 3 | G9: 4 | H9: 4 | I9: 4 | J9: 4 | K9: 2 | L9: 3 | M9: 3 | N9: 4 | O9: 3 | P9: 2 | Q9: 2 | R9: 4 | S9: 3 | T9: 3 | U9: 4 | V9: 3 | W9: 4 | X9: 3 | Y9: 4 | Z9: 4 | AA9: 4 | AB9: 2 | AC9: 3 | AD9: 3 | AE9: 2 | AF9: 2 | AG9: 3 | AI9: =AVERAGE(B9:AG9) -> 3.1875 | AJ9: =STDEVP(B9:AG9) -> 0.76801286 | AK9: =1.96*AJ9/SQRT(32) -> 0.26610288
A10: Fehn_i_Book_arrival_sh_10_to_9 | B10: 4 | C10: 3 | D10: 3 | E10: 3 | F10: 3 | G10: 4 | H10: 3 | I10: 3 | J10: 4 | K10: 2 | L10: 3 | M10: 3 | N10: 4 | O10: 2 | P10: 2 | Q10: 1 | R10: 3 | S10: 2 | T10: 3 | U10: 4 | V10: 3 | W10: 1 | X10: 2 | Y10: 3 | Z10: 2 | AA10: 3 | AB10: 4 | AC10: 4 | AD10: 3 | AE10: 3 | AF10: 2 | AG10: 2 | AI10: =AVERAGE(B10:AG10) -> 2.84375 | AJ10: =STDEVP(B10:AG10) -> 0.83326823 | AK10: =1.96*AJ10/SQRT(32) -> 0.28871271
A11: Holes_Book_arrival_bh_8_to_10 | B11: 1 | C11: 1 | D11: 1 | E11: 1 | F11: 1 | G11: 1 | H11: 1 | I11: 2 | J11: 1 | K11: 1 | L11: 1 | M11: 2 | N11: 1 | O11: 2 | P11: 1 | Q11: 1 | R11: 1 | S11: 1 | T11: 1 | U11: 1 | V11: 1 | W11: 1 | X11: 1 | Y11: 2 | Z11: 1 | AA11: 1 | AB11: 1 | AC11: 1 | AD11: 1 | AE11: 1 | AF11: 1 | AG11: 1 | AI11: =AVERAGE(B11:AG11) -> 1.125 | AJ11: =STDEVP(B11:AG11) -> 0.33071891 | AK11: =1.96*AJ11/SQRT(32) -> 0.11458826
A12: Holes_Book_arrival_bh_10_to_8 | B12: 1 | C12: 1 | D12: 1 | E12: 1 | F12: 1 | G12: 1 | H12: 1 | I12: 2 | J12: 1 | K12: 1 | L12: 1 | M12: 1 | N12: 1 | O12: 1 | P12: 1 | Q12: 1 | R12: 1 | S12: 2 | T12: 1 | U12: 1 | V12: 2 | W12: 1 | X12: 1 | Y12: 2 | Z12: 1 | AA12: 1 | AB12: 1 | AC12: 1 | AD12: 1 | AE12: 1 | AF12: 1 | AG12: 1 | AI12: =AVERAGE(B12:AG12) -> 1.125 | AJ12: =STDEVP(B12:AG12) -> 0.33071891 | AK12: =1.96*AJ12/SQRT(32) -> 0.11458826
A13: Holes_Book_arrival_sh_8_to_9 | B13: 1 | C13: 1 | D13: 1 | E13: 1 | F13: 1 | G13: 2 | H13: 1 | I13: 2 | J13: 2 | K13: 1 | L13: 1 | M13: 1 | N13: 2 | O13: 1 | P13: 1 | Q13: 1 | R13: 2 | S13: 1 | T13: 1 | U13: 1 | V13: 1 | W13: 1 | X13: 1 | Y13: 2 | Z13: 1 | AA13: 2 | AB13: 2 | AC13: 2 | AD13: 1 | AE13: 1 | AF13: 2 | AG13: 1 | AI13: =AVERAGE(B13:AG13) -> 1.3125 | AJ13: =STDEVP(B13:AG13) -> 0.46351241 | AK13: =1.96*AJ13/SQRT(32) -> 0.16059885
A14: Holes_Book_arrival_sh_10_to_9 | B14: 1 | C14: 1 | D14: 2 | E14: 1 | F14: 1 | G14: 2 | H14: 1 | I14: 2 | J14: 2 | K14: 1 | L14: 1 | M14: 3 | N14: 1 | O14: 1 | P14: 1 | Q14: 1 | R14: 2 | S14: 1 | T14: 1 | U14: 1 | V14: 1 | W14: 1 | X14: 1 | Y14: 2 | Z14: 1 | AA14: 1 | AB14: 1 | AC14: 1 | AD14: 2 | AE14: 1 | AF14: 1 | AG14: 1 | AI14: =AVERAGE(B14:AG14) -> 1.28125 | AJ14: =STDEVP(B14:AG14) -> 0.51443993 | AK14: =1.96*AJ14/SQRT(32) -> 0.17824434
... A104: newspaper_cam_04_qp44 | B104: 1 | C104: 1 | D104: 1 | E104: 1 | F104: 1 | G104: 1 | H104: 1 | I104: 2 | J104: 1 | K104: 1 | L104: 1 | M104: 1 | N104: 1 | O104: 2 | P104: 1 | Q104: 1 | R104: 1 | S104: 1 | T104: 1 | U104: 1 | V104: 2 | W104: 2 | X104: 2 | Y104: 2 | Z104: 1 | AA104: 1 | AB104: 2 | AC104: 1 | AD104: 1 | AE104: 1 | AF104: 1 | AG104: 1 | AI104: =AVERAGE(B104:AG104) -> 1.21875 | AJ104: =STDEVP(B104:AG104) -> 0.41339864 | AK104: =1.96*AJ104/SQRT(32) -> 0.14323532

Sheet DMOS
H1: SUBJECTS' RESULTS
B2: 1 | C2: 2 | D2: 3 | E2: 4 | F2: 5 | G2: 6 | H2: 7 | I2: 8 | J2: 9 | K2: 10 | L2: 11 | M2: 12 | N2: 13 | O2: 14 | P2: 15 | Q2: 16 | R2: 17 | S2: 18 | T2: 19 | U2: 20 | V2: 21 | W2: 22 | X2: 23 | Y2: 24 | Z2: 25 | AA2: 26 | AB2: 27 | AC2: 28 | AD2: 29 | AE2: 30 | AF2: 31 | AG2: 32 | AI2: DMOS | AJ2: MOS
A3: Book_arrival_A1_8_to_10.avi | B3: 2 | C3: 1 | D3: 2 | E3: 3 | F3: 3 | G3: 2 | H3: 2 | I3: 4 | J3: 2 | K3: 1 | L3: 1 | M3: 2 | N3: 2 | O3: 2 | P3: 2 | Q3: 1 | R3: 3 | S3: 2 | T3: 2 | U3: 2 | V3: 3 | W3: 1 | X3: 2 | Y3: 3 | Z3: 3 | AA3: 3 | AB3: 4 | AC3: 2 | AD3: 2 | AE3: 3 | AF3: 2 | AG3: 2 | AI3: =5+AVERAGE(B3:AG3)-MOS!AI33 -> 2.9375 | AJ3: =AVERAGE(B3:AG3) -> 2.21875
A4: Book_arrival_A1_10_to_8.avi | B4: 2 | C4: 2 | D4: 2 | E4: 3 | F4: 3 | G4: 3 | H4: 2 | I4: 3 | J4: 4 | K4: 1 | L4: 1 | M4: 2 | N4: 2 | O4: 3 | P4: 3 | Q4: 1 | R4: 4 | S4: 1 | T4: 3 | U4: 2 | V4: 2 | W4: 2 | X4: 1 | Y4: 1 | Z4: 3 | AA4: 3 | AB4: 2 | AC4: 2 | AD4: 1 | AE4: 2 | AF4: 1 | AG4: 2 | AI4: =5+AVERAGE(B4:AG4)-MOS!AI31 -> 3.1875 | AJ4: =AVERAGE(B4:AG4) -> 2.15625
A5: Book_arrival_A1_8_to_9.avi | B5: 4 | C5: 2 | D5: 4 | E5: 4 | F5: 3 | G5: 4 | H5: 4 | I5: 5 | J5: 3 | K5: 2 | L5: 3 | M5: 4 | N5: 4 | O5: 4 | P5: 3 | Q5: 2 | R5: 4 | S5: 4 | T5: 4 | U5: 3 | V5: 4 | W5: 3 | X5: 4 | Y5: 1 | Z5: 4 | AA5: 4 | AB5: 4 | AC5: 3 | AD5: 3 | AE5: 4 | AF5: 2 | AG5: 3 | AI5: =5+AVERAGE(B5:AG5)-MOS!AI32 -> 4.40625 | AJ5: =AVERAGE(B5:AG5) -> 3.40625
A6: Book_arrival_A1_10_to_9.avi | B6: 4 | C6: 4 | D6: 3 | E6: 3 | F6: 3 | G6: 5 | H6: 4 | I6: 5 | J6: 5 | K6: 2 | L6: 2 | M6: 4 | N6: 3 | O6: 3 | P6: 3 | Q6: 4 | R6: 4 | S6: 4 | T6: 4 | U6: 4 | V6: 4 | W6: 4 | X6: 3 | Y6: 4 | Z6: 3 | AA6: 4 | AB6: 3 | AC6: 3 | AD6: 4 | AE6: 3 | AF6: 3 | AG6: 3 | AI6: =5+AVERAGE(B6:AG6)-MOS!AI32 -> 4.5625 | AJ6: =AVERAGE(B6:AG6) -> 3.5625
A7: Book_arrival_A2_8_to_10.avi | B7: 3 | C7: 3 | D7: 2 | E7: 2 | F7: 2 | G7: 1 | H7: 1 | I7: 3 | J7: 3 | K7: 1 | L7: 1 | M7: 2 | N7: 2 | O7: 2 | P7: 1 | Q7: 1 | R7: 3 | S7: 1 | T7: 2 | U7: 2 | V7: 2 | W7: 2 | X7: 1 | Y7: 4 | Z7: 3 | AA7: 3 | AB7: 2 | AC7: 2 | AD7: 2 | AE7: 3 | AF7: 1 | AG7: 2 | AI7: =5+AVERAGE(B7:AG7)-MOS!AI33 -> 2.75 | AJ7: =AVERAGE(B7:AG7) -> 2.03125
A8: Book_arrival_A2_10_to_8.avi | B8: 3 | C8: 1 | D8: 3 | E8: 2 | F8: 2 | G8: 2 | H8: 2 | I8: 3 | J8: 3 | K8: 1 | L8: 1 | M8: 2 | N8: 2 | O8: 2 | P8: 2 | Q8: 1 | R8: 3 | S8: 1 | T8: 2 | U8: 3 | V8: 2 | W8: 2 | X8: 3 | Y8: 3 | Z8: 2 | AA8: 2 | AB8: 2 | AC8: 2 | AD8: 1 | AE8: 1 | AF8: 1 | AG8: 2 | AI8: =5+AVERAGE(B8:AG8)-MOS!AI31 -> 3.03125 | AJ8: =AVERAGE(B8:AG8) -> 2
A9: Book_arrival_A2_8_to_9.avi | B9: 4 | C9: 2 | D9: 4 | E9: 3 | F9: 3 | G9: 4 | H9: 4 | I9: 4 | J9: 4 | K9: 2 | L9: 3 | M9: 3 | N9: 4 | O9: 3 | P9: 2 | Q9: 2 | R9: 4 | S9: 3 | T9: 3 | U9: 4 | V9: 3 | W9: 4 | X9: 3 | Y9: 4 | Z9: 4 | AA9: 4 | AB9: 2 | AC9: 3 | AD9: 3 | AE9: 2 | AF9: 2 | AG9: 3 | AI9: =5+AVERAGE(B9:AG9)-MOS!AI32 -> 4.1875 | AJ9: =AVERAGE(B9:AG9) -> 3.1875
A10: Book_arrival_A2_10_to_9.avi | B10: 4 | C10: 3 | D10: 3 | E10: 3 | F10: 3 | G10: 4 | H10: 3 | I10: 3 | J10: 4 | K10: 2 | L10: 3 | M10: 3 | N10: 4 | O10: 2 | P10: 2 | Q10: 1 | R10: 3 | S10: 2 | T10: 3 | U10: 4 | V10: 3 | W10: 1 | X10: 2 | Y10: 3 | Z10: 2 | AA10: 3 | AB10: 4 | AC10: 4 | AD10: 3 | AE10: 3 | AF10: 2 | AG10: 2 | AI10: =5+AVERAGE(B10:AG10)-MOS!AI32 -> 3.84375 | AJ10: =AVERAGE(B10:AG10) -> 2.84375
A11: Book_arrival_A7_8_to_10.avi | B11: 1 | C11: 1 | D11: 1 | E11: 1 | F11: 1 | G11: 1 | H11: 1 | I11: 2 | J11: 1 | K11: 1 | L11: 1 | M11: 2 | N11: 1 | O11: 2 | P11: 1 | Q11: 1 | R11: 1 | S11: 1 | T11: 1 | U11: 1 | V11: 1 | W11: 1 | X11: 1 | Y11: 2 | Z11: 1 | AA11: 1 | AB11: 1 | AC11: 1 | AD11: 1 | AE11: 1 | AF11: 1 | AG11: 1 | AI11: =5+AVERAGE(B11:AG11)-MOS!AI33 -> 1.84375 | AJ11: =AVERAGE(B11:AG11) -> 1.125
A12: Book_arrival_A7_10_to_8.avi | B12: 1 | C12: 1 | D12: 1 | E12: 1 | F12: 1 | G12: 1 | H12: 1 | I12: 2 | J12: 1 | K12: 1 | L12: 1 | M12: 1 | N12: 1 | O12: 1 | P12: 1 | Q12: 1 | R12: 1 | S12: 2 | T12: 1 | U12: 1 | V12: 2 | W12: 1 | X12: 1 | Y12: 2 | Z12: 1 | AA12: 1 | AB12: 1 | AC12: 1 | AD12: 1 | AE12: 1 | AF12: 1 | AG12: 1 | AI12: =5+AVERAGE(B12:AG12)-MOS!AI31 -> 2.15625 | AJ12: =AVERAGE(B12:AG12) -> 1.125
A13: Book_arrival_A7_8_to_9.avi | B13: 1 | C13: 1 | D13: 1 | E13: 1 | F13: 1 | G13: 2 | H13: 1 | I13: 2 | J13: 2 | K13: 1 | L13: 1 | M13: 1 | N13: 2 | O13: 1 | P13: 1 | Q13: 1 | R13: 2 | S13: 1 | T13: 1 | U13: 1 | V13: 1 | W13: 1 | X13: 1 | Y13: 2 | Z13: 1 | AA13: 2 | AB13: 2 | AC13: 2 | AD13: 1 | AE13: 1 | AF13: 2 | AG13: 1 | AI13: =5+AVERAGE(B13:AG13)-MOS!AI32 -> 2.3125 | AJ13: =AVERAGE(B13:AG13) -> 1.3125
A14: Book_arrival_A7_10_to_9.avi | B14: 1 | C14: 1 | D14: 2 | E14: 1 | F14: 1 | G14: 2 | H14: 1 | I14: 2 | J14: 2 | K14: 1 | L14: 1 | M14: 3 | N14: 1 | O14: 1 | P14: 1 | Q14: 1 | R14: 2 | S14: 1 | T14: 1 | U14: 1 | V14: 1 | W14: 1 | X14: 1 | Y14: 2 | Z14: 1 | AA14: 1 | AB14: 1 | AC14: 1 | AD14: 2 | AE14: 1 | AF14: 1 | AG14: 1 | AI14: =5+AVERAGE(B14:AG14)-MOS!AI32 -> 2.28125 | AJ14: =AVERAGE(B14:AG14) -> 1.28125
A15: Book_arrival_A6_8_to_10.avi | B15: 3 | C15: 3 | D15: 2 | E15: 2 | F15: 2 | G15: 2 | H15: 2 | I15: 3 | J15: 3 | K15: 1 | L15: 2 | M15: 2 | N15: 2 | O15: 2 | P15: 2 | Q15: 1 | R15: 3 | S15: 1 | T15: 2 | U15: 3 | V15: 2 | W15: 1 | X15: 2 | Y15: 1 | Z15: 2 | AA15: 2 | AB15: 2 | AC15: 2 | AD15: 2 | AE15: 2 | AF15: 1 | AG15: 2 | AI15: =5+AVERAGE(B15:AG15)-MOS!AI33 -> 2.71875 | AJ15: =AVERAGE(B15:AG15) -> 2
A16: Book_arrival_A6_10_to_8.avi | B16: 2 | C16: 2 | D16: 2 | E16: 2 | F16: 1 | G16: 2 | H16: 2 | I16: 3 | J16: 3 | K16: 1 | L16: 2 | M16: 2 | N16: 2 | O16: 2 | P16: 2 | Q16: 1 | R16: 3 | S16: 1 | T16: 2 | U16: 3 | V16: 2 | W16: 2 | X16: 1 | Y16: 1 | Z16: 2 | AA16: 2 | AB16: 2 | AC16: 2 | AD16: 2 | AE16: 1 | AF16: 1 | AG16: 2 | AI16: =5+AVERAGE(B16:AG16)-MOS!AI31 -> 2.90625 | AJ16: =AVERAGE(B16:AG16) -> 1.875
A17: Book_arrival_A6_8_to_9.avi | B17: 3 | C17: 4 | D17: 3 | E17: 2 | F17: 3 | G17: 3 | H17: 3 | I17: 3 | J17: 4 | K17: 3 | L17: 3 | M17: 4 | N17: 4 | O17: 4 | P17: 3 | Q17: 3 | R17: 4 | S17: 3 | T17: 3 | U17: 3 | V17: 4 | W17: 3 | X17: 3 | Y17: 3 | Z17: 3 | AA17: 3 | AB17: 3 | AC17: 3 | AD17: 3 | AE17: 3 | AF17: 2 | AG17: 4 | AI17: =5+AVERAGE(B17:AG17)-MOS!AI32 -> 4.1875 | AJ17: =AVERAGE(B17:AG17) -> 3.1875
A18: Book_arrival_A6_10_to_9.avi | B18: 2 | C18: 1 | D18: 2 | E18: 3 | F18: 2 | G18: 2 | H18: 2 | I18: 3 | J18: 3 | K18: 2 | L18: 3 | M18: 2 | N18: 2 | O18: 3 | P18: 3 | Q18: 1 | R18: 3 | S18: 3 | T18: 3 | U18: 2 | V18: 3 | W18: 3 | X18: 2 | Y18: 1 | Z18: 2 | AA18: 3 | AB18: 2 | AC18: 3 | AD18: 2 | AE18: 3 | AF18: 2 | AG18: 3 | AI18: =5+AVERAGE(B18:AG18)-MOS!AI32 -> 3.375 | AJ18: =AVERAGE(B18:AG18) -> 2.375
A19: Book_arrival_A5_8_to_10.avi | B19: 2 | C19: 2 | D19: 2 | E19: 1 | F19: 3 | G19: 3 | H19: 2 | I19: 2 | J19: 2 | K19: 1 | L19: 3 | M19: 3 | N19: 2 | O19: 2 | P19: 2 | Q19: 1 | R19: 3 | S19: 1 | T19: 2 | U19: 2 | V19: 2 | W19: 1 | X19: 2 | Y19: 1 | Z19: 2 | AA19: 2 | AB19: 1 | AC19: 2 | AD19: 3 | AE19: 2 | AF19: 1 | AG19: 2 | AI19: =5+AVERAGE(B19:AG19)-MOS!AI33 -> 2.65625 | AJ19: =AVERAGE(B19:AG19) -> 1.9375
A20: Book_arrival_A5_10_to_8.avi | B20: 2 | C20: 1 | D20: 1 | E20: 2 | F20: 1 | G20: 3 | H20: 1 | I20: 3 | J20: 1 | K20: 1 | L20: 2 | M20: 1 | N20: 2 | O20: 1 | P20: 1 | Q20: 1 | R20: 3 | S20: 1 | T20: 3 | U20: 3 | V20: 2 | W20: 2 | X20: 2 | Y20: 2 | Z20: 2 | AA20: 2 | AB20: 1 | AC20: 2 | AD20: 1 | AE20: 1 | AF20: 1 | AG20: 2 | AI20: =5+AVERAGE(B20:AG20)-MOS!AI31 -> 2.71875 | AJ20: =AVERAGE(B20:AG20) -> 1.6875
A21: Book_arrival_A5_8_to_9.avi | B21: 2 | C21: 2 | D21: 2 | E21: 2 | F21: 3 | G21: 3 | H21: 2 | I21: 3 | J21: 2 | K21: 2 | L21: 3 | M21: 2 | N21: 3 | O21: 3 | P21: 2 | Q21: 2 | R21: 3 | S21: 2 | T21: 3 | U21: 3 | V21: 3 | W21: 2 | X21: 2 | Y21: 3 | Z21: 3 | AA21: 2 | AB21: 3 | AC21: 2 | AD21: 2 | AE21: 2 | AF21: 2 | AG21: 2 | AI21: =5+AVERAGE(B21:AG21)-MOS!AI32 -> 3.40625 | AJ21: =AVERAGE(B21:AG21) -> 2.40625
A22: Book_arrival_A5_10_to_9.avi | B22: 3 | C22: 2 | D22: 2 | E22: 3 | F22: 1 | G22: 2 | H22: 2 | I22: 3 | J22: 3 | K22: 1 | L22: 3 | M22: 3 | N22: 3 | O22: 2 | P22: 2 | Q22: 2 | R22: 3 | S22: 2 | T22: 2 | U22: 3 | V22: 3 | W22: 2 | X22: 2 | Y22: 1 | Z22: 3 | AA22: 3 | AB22: 2 | AC22: 2 | AD22: 2 | AE22: 3 | AF22: 2 | AG22: 3 | AI22: =5+AVERAGE(B22:AG22)-MOS!AI32 -> 3.34375 | AJ22: =AVERAGE(B22:AG22) -> 2.34375
A23: Book_arrival_A3_8_to_10.avi | B23: 2 | C23: 2 | D23: 2 | E23: 2 | F23: 2 | G23: 2 | H23: 2 | I23: 3 | J23: 2 | K23: 1 | L23: 2 | M23: 2 | N23: 2 | O23: 2 | P23: 2 | Q23: 1 | R23: 3 | S23: 2 | T23: 2 | U23: 2 | V23: 3 | W23: 2 | X23: 2 | Y23: 1 | Z23: 2 | AA23: 2 | AB23: 2 | AC23: 2 | AD23: 2 | AE23: 2 | AF23: 1 | AG23: 2 | AI23: =5+AVERAGE(B23:AG23)-MOS!AI33 -> 2.6875 | AJ23: =AVERAGE(B23:AG23) -> 1.96875
A24: Book_arrival_A3_10_to_8.avi | B24: 2 | C24: 2 | D24: 2 | E24: 2 | F24: 2 | G24: 2 | H24: 2 | I24: 3 | J24: 2 | K24: 1 | L24: 2 | M24: 2 | N24: 2 | O24: 3 | P24: 2 | Q24: 1 | R24: 3 | S24: 1 | T24: 2 | U24: 2 | V24: 2 | W24: 2 | X24: 2 | Y24: 1 | Z24: 2 | AA24: 2 | AB24: 3 | AC24: 2 | AD24: 2 | AE24: 2 | AF24: 1 | AG24: 2 | AI24: =5+AVERAGE(B24:AG24)-MOS!AI31 -> 3 | AJ24: =AVERAGE(B24:AG24) -> 1.96875
A25: Book_arrival_A3_8_to_9.avi | B25: 2 | C25: 3 | D25: 3 | E25: 2 | F25: 3 | G25: 3 | H25: 3 | I25: 4 | J25: 3 | K25: 2 | L25: 3 | M25: 3 | N25: 3 | O25: 3 | P25: 2 | Q25: 2 | R25: 4 | S25: 3 | T25: 2 | U25: 4 | V25: 3 | W25: 3 | X25: 3 | Y25: 3 | Z25: 4 | AA25: 4 | AB25: 3 | AC25: 2 | AD25: 3 | AE25: 3 | AF25: 2 | AG25: 3 | AI25: =5+AVERAGE(B25:AG25)-MOS!AI32 -> 3.90625 | AJ25: =AVERAGE(B25:AG25) -> 2.90625
A26: Book_arrival_A3_10_to_9.avi | B26: 2 | C26: 2 | D26: 3 | E26: 3 | F26: 3 | G26: 2 | H26: 2 | I26: 3 | J26: 3 | K26: 2 | L26: 3 | M26: 4 | N26: 3 | O26: 2 | P26: 2 | Q26: 1 | R26: 4 | S26: 3 | T26: 3 | U26: 2 | V26: 3 | W26: 3 | X26: 2 | Y26: 1 | Z26: 2 | AA26: 3 | AB26: 3 | AC26: 2 | AD26: 2 | AE26: 2 | AF26: 1 | AG26: 3 | AI26: =5+AVERAGE(B26:AG26)-MOS!AI32 -> 3.46875 | AJ26: =AVERAGE(B26:AG26) -> 2.46875
A27: Book_arrival_A4_8_to_10.avi | B27: 2 | C27: 2 | D27: 2 | E27: 2 | F27: 2 | G27: 2 | H27: 2 | I27: 3 | J27: 1 | K27: 1 | L27: 2 | M27: 1 | N27: 2 | O27: 3 | P27: 1 | Q27: 1 | R27: 3 | S27: 1 | T27: 2 | U27: 2 | V27: 2 | W27: 2 | X27: 2 | Y27: 1 | Z27: 2 | AA27: 2 | AB27: 2 | AC27: 2 | AD27: 2 | AE27: 2 | AF27: 1 | AG27: 2 | AI27: =5+AVERAGE(B27:AG27)-MOS!AI33 -> 2.5625 | AJ27: =AVERAGE(B27:AG27) -> 1.84375
A28: Book_arrival_A4_10_to_8.avi | B28: 3 | C28: 2 | D28: 2 | E28: 2 | F28: 2 | G28: 2 | H28: 1 | I28: 3 | J28: 2 | K28: 1 | L28: 3 | M28: 2 | N28: 2 | O28: 2 | P28: 2 | Q28: 1 | R28: 3 | S28: 1 | T28: 2 | U28: 2 | V28: 2 | W28: 3 | X28: 1 | Y28: 1 | Z28: 2 | AA28: 2 | AB28: 2 | AC28: 2 | AD28: 1 | AE28: 1 | AF28: 1 | AG28: 2 | AI28: =5+AVERAGE(B28:AG28)-MOS!AI31 -> 2.90625 | AJ28: =AVERAGE(B28:AG28) -> 1.875
A29: Book_arrival_A4_8_to_9.avi | B29: 3 | C29: 3 | D29: 2 | E29: 2 | F29: 3 | G29: 2 | H29: 2 | I29: 3 | J29: 2 | K29: 2 | L29: 3 | M29: 2 | N29: 4 | O29: 2 | P29: 2 | Q29: 1 | R29: 3 | S29: 1 | T29: 3 | U29: 3 | V29: 3 | W29: 2 | X29: 2 | Y29: 3 | Z29: 2 | AA29: 3 | AB29: 3 | AC29: 3 | AD29: 3 | AE29: 2 | AF29: 2 | AG29: 2 | AI29: =5+AVERAGE(B29:AG29)-MOS!AI32 -> 3.4375 | AJ29: =AVERAGE(B29:AG29) -> 2.4375
A30: Book_arrival_A4_10_to_9.avi | B30: 2 | C30: 2 | D30: 3 | E30: 3 | F30: 2 | G30: 3 | H30: 2 | I30: 3 | J30: 3 | K30: 1 | L30: 2 | M30: 2 | N30: 3 | O30: 3 | P30: 2 | Q30: 1 | R30: 3 | S30: 1 | T30: 2 | U30: 2 | V30: 2 | W30: 3 | X30: 2 | Y30: 3 | Z30: 2 | AA30: 3 | AB30: 2 | AC30: 2 | AD30: 2 | AE30: 1 | AF30: 2 | AG30: 3 | AI30: =5+AVERAGE(B30:AG30)-MOS!AI32 -> 3.25 | AJ30: =AVERAGE(B30:AG30) -> 2.25
A31: Book_arrival_cam_08 | B31: 3 | C31: 3 | D31: 4 | E31: 3 | F31: 5 | G31: 5 | H31: 3 | I31: 5 | J31: 5 | K31: 2 | L31: 4 | M31: 3 | N31: 5 | O31: 2 | P31: 3 | Q31: 4 | R31: 4 | S31: 4 | T31: 5 | U31: 5 | V31: 4 | W31: 5 | X31: 3 | Y31: 5 | Z31: 4 | AA31: 4 | AB31: 4 | AC31: 4 | AD31: 4 | AE31: 5 | AF31: 3 | AG31: 5 | AI31: =5+AVERAGE(B31:AG31)-MOS!AI31 -> 5 | AJ31: =AVERAGE(B31:AG31) -> 3.96875
A32: Book_arrival_cam_09 | B32: 4 | C32: 3 | D32: 4 | E32: 3 | F32: 4 | G32: 5 | H32: 3 | I32: 5 | J32: 5 | K32: 2 | L32: 4 | M32: 4 | N32: 4 | O32: 3 | P32: 4 | Q32: 5 | R32: 5 | S32: 4 | T32: 5 | U32: 4 | V32: 5 | W32: 3 | X32: 4 | Y32: 5 | Z32: 4 | AA32: 5 | AB32: 5 | AC32: 4 | AD32: 4 | AE32: 3 | AF32: 2 | AG32: 4 | AI32: =5+AVERAGE(B32:AG32)-MOS!AI32 -> 5 | AJ32: =AVERAGE(B32:AG32) -> 4
A33: Book_arrival_cam_10 | B33: 4 | C33: 4 | D33: 4 | E33: 2 | F33: 5 | G33: 4 | H33: 4 | I33: 4 | J33: 5 | K33: 1 | L33: 4 | M33: 5 | N33: 5 | O33: 5 | P33: 4 | Q33: 5 | R33: 4 | S33: 5 | T33: 5 | U33: 5 | V33: 5 | W33: 4 | X33: 3 | Y33: 4 | Z33: 5 | AA33: 5 | AB33: 5 | AC33: 5 | AD33: 5 | AE33: 4 | AF33: 3 | AG33: 5 | AI33: =5+AVERAGE(B33:AG33)-MOS!AI33 -> 5 | AJ33: =AVERAGE(B33:AG33) -> 4.28125
A34: Book_arrival_cam_08_qp26 | B34: 5 | C34: 3 | D34: 3 | E34: 3 | F34: 5 | G34: 4 | H34: 4 | I34: 4 | J34: 5 | K34: 2 | L34: 4 | M34: 4 | N34: 3 | O34: 4 | P34: 4 | Q34: 5 | R34: 5 | S34: 4 | T34: 5 | U34: 4 | V34: 4 | W34: 4 | X34: 4 | Y34: 4 | Z34: 4 | AA34: 3 | AB34: 3 | AC34: 4 | AD34: 4 | AE34: 4 | AF34: 3 | AG34: 4 | AI34: =5+AVERAGE(B34:AG34)-MOS!AI31 -> 4.9375 | AJ34: =AVERAGE(B34:AG34) -> 3.90625
A35: Book_arrival_cam_08_qp34 | B35: 1 | C35: 4 | D35: 4 | E35: 2 | F35: 3 | G35: 4 | H35: 3 | I35: 3 | J35: 4 | K35: 1 | L35: 3 | M35: 4 | N35: 3 | O35: 3 | P35: 2 | Q35: 3 | R35: 4 | S35: 3 | T35: 4 | U35: 3 | V35: 4 | W35: 3 | X35: 3 | Y35: 3 | Z35: 4 | AA35: 2 | AB35: 1 | AC35: 3 | AD35: 4 | AE35: 3 | AF35: 2 | AG35: 3 | AI35: =5+AVERAGE(B35:AG35)-MOS!AI31 -> 4.03125 | AJ35: =AVERAGE(B35:AG35) -> 3
A36: Book_arrival_cam_08_qp44 | B36: 1 | C36: 1 | D36: 1 | E36: 1 | F36: 1 | G36: 1 | H36: 1 | I36: 2 | J36: 1 | K36: 1 | L36: 1 | M36: 1 | N36: 1 | O36: 1 | P36: 1 | Q36: 1 | R36: 1 | S36: 1 | T36: 1 | U36: 1 | V36: 1 | W36: 1 | X36: 1 | Y36: 2 | Z36: 1 | AA36: 1 | AB36: 1 | AC36: 1 | AD36: 1 | AE36: 1 | AF36: 1 | AG36: 1 | AI36: =5+AVERAGE(B36:AG36)-MOS!AI31 -> 2.09375 | AJ36: =AVERAGE(B36:AG36) -> 1.0625
A37: Lovebird1_A1_6_to_8.avi | B37: 1 | C37: 1 | D37: 2 | E37: 2 | F37: 3 | G37: 1 | H37: 1 | I37: 3 | J37: 2 | K37: 1 | L37: 1 | M37: 2 | N37: 2 | O37: 2 | P37: 2 | Q37: 2 | R37: 3 | S37: 1 | T37: 2 | U37: 2 | V37: 2 | W37: 2 | X37: 3 | Y37: 3 | Z37: 2 | AA37: 2 | AB37: 1 | AC37: 2 | AD37: 2 | AE37: 1 | AF37: 1 | AG37: 2 | AI37: =5+AVERAGE(B37:AG37)-MOS!AI67 -> 2.84375 | AJ37: =AVERAGE(B37:AG37) -> 1.84375
A38: Lovebird1_A1_8_to_6.avi | B38: 2 | C38: 1 | D38: 2 | E38: 3 | F38: 3 | G38: 2 | H38: 1 | I38: 3 | J38: 1 | K38: 1 | L38: 2 | M38: 1 | N38: 2 | O38: 2 | P38: 2 | Q38: 1 | R38: 4 | S38: 1 | T38: 3 | U38: 1 | V38: 2 | W38: 2 | X38: 2 | Y38: 1 | Z38: 2 | AA38: 2 | AB38: 2 | AC38: 3 | AD38: 3 | AE38: 2 | AF38: 1 | AG38: 2 | AI38: =5+AVERAGE(B38:AG38)-MOS!AI65 -> 3.03125 | AJ38: =AVERAGE(B38:AG38) -> 1.9375
A39: Lovebird1_A1_6_to_7.avi | B39: 2 | C39: 3 | D39: 2 | E39: 3 | F39: 3 | G39: 3 | H39: 2 | I39: 4 | J39: 4 | K39: 2 | L39: 2 | M39: 4 | N39: 3 | O39: 3 | P39: 3 | Q39: 2 | R39: 4 | S39: 1 | T39: 4 | U39: 3 | V39: 3 | W39: 3 | X39: 3 | Y39: 3 | Z39: 4 | AA39: 2 | AB39: 3 | AC39: 3 | AD39: 3 | AE39: 3 | AF39: 2 | AG39: 4 | AI39: =5+AVERAGE(B39:AG39)-MOS!AI66 -> 3.65625 | AJ39: =AVERAGE(B39:AG39) -> 2.90625
A40: Lovebird1_A1_8_to_7.avi | B40: 2 | C40: 3 | D40: 3 | E40: 3 | F40: 3 | G40: 2 | H40: 2 | I40: 4 | J40: 4 | K40: 1 | L40: 2 | M40: 4 | N40: 3 | O40: 3 | P40: 4 | Q40: 3 | R40: 4 | S40: 2 | T40: 4 | U40: 3 | V40: 3 | W40: 3 | X40: 3 | Y40: 4 | Z40: 2 | AA40: 2 | AB40: 2 | AC40: 2 | AD40: 3 | AE40: 2 | AF40: 2 | AG40: 2 | AI40: =5+AVERAGE(B40:AG40)-MOS!AI66 -> 3.53125 | AJ40: =AVERAGE(B40:AG40) -> 2.78125
...
